<?xml version="1.0"?>
<robot xmlns:xacro="http://www.ros.org/wiki/xacro">

    <xacro:include filename="inertial_macros.xacro"/>

    <material name= "white">
        <color rgba="1 1 1 1"/>
    </material>
    <material name= "black">
        <color rgba="0 0 0 1"/>
    </material>
    <material name= "orange">
        <color rgba="1 0 0 1"/>
    </material>
    <material name= "green">
        <color rgba="0 1 0 1"/>
    </material>

    <!-- BASE LINK -->
    <link name = "base_link">
    
    </link>

    <!-- CHASSIS LINK -->

    <joint name="chassis_joint" type="fixed">
        <parent link="base_link"/>
        <child link="chassis"/>
        <origin xyz="-0.5 0 0"/>
    </joint>

    <link name="chassis">
        <visual>
            <origin xyz="0.5 0 0.1" />
            <geometry>
                <box size="1 0.5 0.2"/>
            </geometry>
            <material name="white"/>
        </visual>
        
        <collision>
            <origin xyz="0.5 0 0.1" />
            <geometry>
                <box size="1 0.5 0.2"/>
            </geometry>
        </collision>
        <xacro:inertial_box mass="50" x="1" y="0.5" z="0.2">
            <origin xyz="0.5 0 0.1" rpy="0 0 0"/>
        </xacro:inertial_box>
    </link>

    <!--LEFT WHEEL LINK-->

    <joint name="left_wheel_joint" type="continuous">
        <parent link="base_link"/>
        <child link="left_wheel"/>
        <origin xyz="0 0.2 0" rpy="-${pi/2} 0 0"/>
        <axis xyz="0 0 1"/>
    </joint>

    <link name="left_wheel">
        <visual>
            <geometry>
                <cylinder length="0.1" radius="0.1"/>
            </geometry>
            <material name="green"/>
        </visual>

        <collision>
            <geometry>
                <cylinder length="0.1" radius="0.1"/>
            </geometry>
        </collision>
        <xacro:inertial_cylinder mass="5" length="0.1" radius="0.1">
            <origin xyz="0 0 0" rpy="0 0 0"/>
        </xacro:inertial_cylinder>
    </link>

    <!--RIGHT WHEEL LINK-->

    <joint name="right_wheel_joint" type="continuous">
        <parent link="base_link"/>
        <child link="right_wheel"/>
        <origin xyz="0 -0.2 0" rpy="${pi/2} 0 0"/>
        <axis xyz="0 0 -1"/>
    </joint>

    <link name="right_wheel">
        <visual>
            <geometry>
                <cylinder length="0.1" radius="0.1"/>
            </geometry>
            <material name="green"/>
        </visual>

        <collision>
            <geometry>
                <cylinder length="0.1" radius="0.1"/>
            </geometry>
        </collision>
        <xacro:inertial_cylinder mass="5" length="0.1" radius="0.1">
            <origin xyz="0 0 0" rpy="0 0 0"/>
        </xacro:inertial_cylinder>
    </link>

    <!-- FRONT CASTER WHEEL LINK-->

    <joint name="front_caster_wheel_joint" type="fixed">
        <parent link="chassis"/>
        <child link="front_caster_wheel"/>
        <origin xyz="0.9 0 0"/>
    </joint>

    <link name="front_caster_wheel">
        <visual>
            <geometry>
                <sphere radius="0.1"/>
            </geometry>
            <material name="black"/>
        </visual>

        <collision>
            <geometry>
                <sphere radius="0.1"/>
            </geometry>
        </collision>
        <xacro:inertial_sphere mass="2" radius="0.1">
            <origin xyz="0 0 0" rpy="0 0 0"/>
        </xacro:inertial_sphere>
    </link>

    <!-- BACK CASTER WHEEL LINK-->

    <joint name="back_caster_wheel_joint" type="fixed">
        <parent link="chassis"/>
        <child link="back_caster_wheel"/>
        <origin xyz="0.1 0 0"/>
    </joint>

    <link name="back_caster_wheel">
        <visual>
            <geometry>
                <sphere radius="0.1"/>
            </geometry>
            <material name="black"/>
        </visual>

        <collision>
            <geometry>
                <sphere radius="0.1"/>
            </geometry>
        </collision>
    </link>

</robot>